2018-08-09 17:21:45,405,13292,django.request,ERROR,exception.py:118,Internal Server Error: /
Traceback (most recent call last):
  File "D:\Program Files (x86)\python\lib\site-packages\django\core\handlers\exception.py", line 35, in inner
    response = get_response(request)
  File "D:\Program Files (x86)\python\lib\site-packages\django\core\handlers\base.py", line 158, in _get_response
    response = self.process_exception_by_middleware(e, request)
  File "D:\Program Files (x86)\python\lib\site-packages\django\core\handlers\base.py", line 156, in _get_response
    response = response.render()
  File "D:\Program Files (x86)\python\lib\site-packages\django\template\response.py", line 106, in render
    self.content = self.rendered_content
  File "D:\Program Files (x86)\python\lib\site-packages\django\template\response.py", line 81, in rendered_content
    template = self.resolve_template(self.template_name)
  File "D:\Program Files (x86)\python\lib\site-packages\django\template\response.py", line 63, in resolve_template
    return select_template(template, using=self.using)
  File "D:\Program Files (x86)\python\lib\site-packages\django\template\loader.py", line 47, in select_template
    raise TemplateDoesNotExist(', '.join(template_name_list), chain=chain)
django.template.exceptions.TemplateDoesNotExist: index.html
2018-08-09 17:21:45,889,13292,django.server,ERROR,basehttp.py:124,"GET / HTTP/1.1" 500 83571
2018-08-09 18:33:36,619,9808,django.request,ERROR,exception.py:118,Internal Server Error: /api/company/feedView
Traceback (most recent call last):
  File "D:\Program Files (x86)\python\lib\site-packages\django\core\handlers\exception.py", line 35, in inner
    response = get_response(request)
  File "D:\Program Files (x86)\python\lib\site-packages\django\core\handlers\base.py", line 128, in _get_response
    response = self.process_exception_by_middleware(e, request)
  File "D:\Program Files (x86)\python\lib\site-packages\django\core\handlers\base.py", line 126, in _get_response
    response = wrapped_callback(request, *callback_args, **callback_kwargs)
  File "D:\Program Files (x86)\python\lib\site-packages\django\views\decorators\csrf.py", line 54, in wrapped_view
    return view_func(*args, **kwargs)
  File "D:\Program Files (x86)\python\lib\site-packages\django\views\generic\base.py", line 69, in view
    return self.dispatch(request, *args, **kwargs)
  File "D:\Program Files (x86)\python\lib\site-packages\rest_framework\views.py", line 489, in dispatch
    response = self.handle_exception(exc)
  File "D:\Program Files (x86)\python\lib\site-packages\rest_framework\views.py", line 451, in handle_exception
    self.raise_uncaught_exception(exc)
  File "D:\Program Files (x86)\python\lib\site-packages\rest_framework\views.py", line 486, in dispatch
    response = handler(request, *args, **kwargs)
  File "E:\project\ItTest\blackList\api\Interview.py", line 56, in post
    if feed_serializer.is_valid():
  File "D:\Program Files (x86)\python\lib\site-packages\rest_framework\serializers.py", line 236, in is_valid
    self._validated_data = self.run_validation(self.initial_data)
  File "D:\Program Files (x86)\python\lib\site-packages\rest_framework\serializers.py", line 435, in run_validation
    value = self.to_internal_value(data)
  File "D:\Program Files (x86)\python\lib\site-packages\rest_framework\serializers.py", line 459, in to_internal_value
    fields = self._writable_fields
  File "D:\Program Files (x86)\python\lib\site-packages\django\utils\functional.py", line 36, in __get__
    res = instance.__dict__[self.name] = self.func(instance)
  File "D:\Program Files (x86)\python\lib\site-packages\rest_framework\serializers.py", line 370, in _writable_fields
    field for field in self.fields.values()
  File "D:\Program Files (x86)\python\lib\site-packages\rest_framework\serializers.py", line 363, in fields
    for key, value in self.get_fields().items():
  File "D:\Program Files (x86)\python\lib\site-packages\rest_framework\serializers.py", line 1022, in get_fields
    source, info, model, depth
  File "D:\Program Files (x86)\python\lib\site-packages\rest_framework\serializers.py", line 1167, in build_field
    return self.build_unknown_field(field_name, model_class)
  File "D:\Program Files (x86)\python\lib\site-packages\rest_framework\serializers.py", line 1279, in build_unknown_field
    (field_name, model_class.__name__)
django.core.exceptions.ImproperlyConfigured: Field name `SalaryRange` is not valid for model `BlackList`.
2018-08-09 18:33:37,216,9808,django.server,ERROR,basehttp.py:124,"POST /api/company/feedView HTTP/1.1" 500 19220
2018-08-10 10:58:17,935,14296,django.request,ERROR,exception.py:118,Internal Server Error: /api/company/updata
Traceback (most recent call last):
  File "D:\Program Files (x86)\python\lib\site-packages\django_redis\cache.py", line 32, in _decorator
    return method(self, *args, **kwargs)
  File "D:\Program Files (x86)\python\lib\site-packages\django_redis\cache.py", line 124, in has_key
    return self.client.has_key(*args, **kwargs)
  File "D:\Program Files (x86)\python\lib\site-packages\django_redis\client\default.py", line 477, in has_key
    raise ConnectionInterrupted(connection=client, parent=e)
django_redis.exceptions.ConnectionInterrupted: Redis ConnectionError: Error 11001 connecting to your_host_ip:6379. getaddrinfo failed.

During handling of the above exception, another exception occurred:

Traceback (most recent call last):
  File "D:\Program Files (x86)\python\lib\site-packages\django\core\handlers\exception.py", line 35, in inner
    response = get_response(request)
  File "E:\project\ItTest\MW\middleware.py", line 12, in __call__
    if cache.has_key(ip):
  File "D:\Program Files (x86)\python\lib\site-packages\django_redis\cache.py", line 39, in _decorator
    raise e.parent
  File "D:\Program Files (x86)\python\lib\site-packages\django_redis\client\default.py", line 475, in has_key
    return client.exists(key)
  File "D:\Program Files (x86)\python\lib\site-packages\redis\client.py", line 951, in exists
    return self.execute_command('EXISTS', name)
  File "D:\Program Files (x86)\python\lib\site-packages\redis\client.py", line 673, in execute_command
    connection.send_command(*args)
  File "D:\Program Files (x86)\python\lib\site-packages\redis\connection.py", line 610, in send_command
    self.send_packed_command(self.pack_command(*args))
  File "D:\Program Files (x86)\python\lib\site-packages\redis\connection.py", line 585, in send_packed_command
    self.connect()
  File "D:\Program Files (x86)\python\lib\site-packages\redis\connection.py", line 489, in connect
    raise ConnectionError(self._error_message(e))
redis.exceptions.ConnectionError: Error 11001 connecting to your_host_ip:6379. getaddrinfo failed.
2018-08-10 10:58:18,603,14296,django.server,ERROR,basehttp.py:124,"POST /api/company/updata HTTP/1.1" 500 98301
2018-08-10 11:15:37,187,6512,django.request,ERROR,exception.py:118,Internal Server Error: /api/company/updata
Traceback (most recent call last):
  File "D:\Program Files (x86)\python\lib\site-packages\django\core\handlers\exception.py", line 35, in inner
    response = get_response(request)
  File "D:\Program Files (x86)\python\lib\site-packages\django\core\handlers\base.py", line 128, in _get_response
    response = self.process_exception_by_middleware(e, request)
  File "D:\Program Files (x86)\python\lib\site-packages\django\core\handlers\base.py", line 126, in _get_response
    response = wrapped_callback(request, *callback_args, **callback_kwargs)
  File "D:\Program Files (x86)\python\lib\site-packages\django\views\decorators\csrf.py", line 54, in wrapped_view
    return view_func(*args, **kwargs)
  File "D:\Program Files (x86)\python\lib\site-packages\django\views\generic\base.py", line 69, in view
    return self.dispatch(request, *args, **kwargs)
  File "D:\Program Files (x86)\python\lib\site-packages\rest_framework\views.py", line 489, in dispatch
    response = self.handle_exception(exc)
  File "D:\Program Files (x86)\python\lib\site-packages\rest_framework\views.py", line 451, in handle_exception
    self.raise_uncaught_exception(exc)
  File "D:\Program Files (x86)\python\lib\site-packages\rest_framework\views.py", line 486, in dispatch
    response = handler(request, *args, **kwargs)
  File "E:\project\ItTest\blackList\api\Interview.py", line 73, in post
    file_to_save = open(os.path.join("1.txt", _file.name), "wb+")
FileNotFoundError: [Errno 2] No such file or directory: '1.txt\\output.txt'
2018-08-10 11:15:37,472,6512,django.server,ERROR,basehttp.py:124,"POST /api/company/updata HTTP/1.1" 500 17785
2018-08-10 11:18:13,529,10204,django.request,ERROR,exception.py:118,Internal Server Error: /api/company/updata
Traceback (most recent call last):
  File "D:\Program Files (x86)\python\lib\site-packages\django\core\handlers\exception.py", line 35, in inner
    response = get_response(request)
  File "D:\Program Files (x86)\python\lib\site-packages\django\core\handlers\base.py", line 128, in _get_response
    response = self.process_exception_by_middleware(e, request)
  File "D:\Program Files (x86)\python\lib\site-packages\django\core\handlers\base.py", line 126, in _get_response
    response = wrapped_callback(request, *callback_args, **callback_kwargs)
  File "D:\Program Files (x86)\python\lib\site-packages\django\views\decorators\csrf.py", line 54, in wrapped_view
    return view_func(*args, **kwargs)
  File "D:\Program Files (x86)\python\lib\site-packages\django\views\generic\base.py", line 69, in view
    return self.dispatch(request, *args, **kwargs)
  File "D:\Program Files (x86)\python\lib\site-packages\rest_framework\views.py", line 489, in dispatch
    response = self.handle_exception(exc)
  File "D:\Program Files (x86)\python\lib\site-packages\rest_framework\views.py", line 451, in handle_exception
    self.raise_uncaught_exception(exc)
  File "D:\Program Files (x86)\python\lib\site-packages\rest_framework\views.py", line 486, in dispatch
    response = handler(request, *args, **kwargs)
  File "E:\project\ItTest\blackList\api\Interview.py", line 72, in post
    file_to_save = open(os.path.join("./data", _file.name), "wb+")
FileNotFoundError: [Errno 2] No such file or directory: './data\\output.txt'
2018-08-10 11:18:13,829,10204,django.server,ERROR,basehttp.py:124,"POST /api/company/updata HTTP/1.1" 500 17788
2018-08-10 11:18:40,326,13284,django.request,ERROR,exception.py:118,Internal Server Error: /api/company/updata
Traceback (most recent call last):
  File "D:\Program Files (x86)\python\lib\site-packages\django\core\handlers\exception.py", line 35, in inner
    response = get_response(request)
  File "D:\Program Files (x86)\python\lib\site-packages\django\core\handlers\base.py", line 128, in _get_response
    response = self.process_exception_by_middleware(e, request)
  File "D:\Program Files (x86)\python\lib\site-packages\django\core\handlers\base.py", line 126, in _get_response
    response = wrapped_callback(request, *callback_args, **callback_kwargs)
  File "D:\Program Files (x86)\python\lib\site-packages\django\views\decorators\csrf.py", line 54, in wrapped_view
    return view_func(*args, **kwargs)
  File "D:\Program Files (x86)\python\lib\site-packages\django\views\generic\base.py", line 69, in view
    return self.dispatch(request, *args, **kwargs)
  File "D:\Program Files (x86)\python\lib\site-packages\rest_framework\views.py", line 489, in dispatch
    response = self.handle_exception(exc)
  File "D:\Program Files (x86)\python\lib\site-packages\rest_framework\views.py", line 451, in handle_exception
    self.raise_uncaught_exception(exc)
  File "D:\Program Files (x86)\python\lib\site-packages\rest_framework\views.py", line 486, in dispatch
    response = handler(request, *args, **kwargs)
  File "E:\project\ItTest\blackList\api\Interview.py", line 72, in post
    file_to_save = open(os.path.join("\data", _file.name), "wb+")
FileNotFoundError: [Errno 2] No such file or directory: '\\data\\output.txt'
2018-08-10 11:18:40,512,13284,django.server,ERROR,basehttp.py:124,"POST /api/company/updata HTTP/1.1" 500 17787
2018-08-10 13:31:56,971,10280,django.request,ERROR,exception.py:118,Internal Server Error: /api/company/download
Traceback (most recent call last):
  File "D:\Program Files (x86)\python\lib\site-packages\django\core\handlers\exception.py", line 35, in inner
    response = get_response(request)
  File "D:\Program Files (x86)\python\lib\site-packages\django\core\handlers\base.py", line 128, in _get_response
    response = self.process_exception_by_middleware(e, request)
  File "D:\Program Files (x86)\python\lib\site-packages\django\core\handlers\base.py", line 126, in _get_response
    response = wrapped_callback(request, *callback_args, **callback_kwargs)
  File "E:\project\ItTest\blackList\api\Interview.py", line 93, in download_doc
    _file = open(url, "rb")
FileNotFoundError: [Errno 2] No such file or directory: '0'
2018-08-10 13:31:57,905,10280,django.server,ERROR,basehttp.py:124,"GET /api/company/download?url=0 HTTP/1.1" 500 70987
2018-08-10 13:32:35,177,10280,django.request,ERROR,exception.py:118,Internal Server Error: /api/company/download
Traceback (most recent call last):
  File "D:\Program Files (x86)\python\lib\site-packages\django\core\handlers\exception.py", line 35, in inner
    response = get_response(request)
  File "D:\Program Files (x86)\python\lib\site-packages\django\core\handlers\base.py", line 128, in _get_response
    response = self.process_exception_by_middleware(e, request)
  File "D:\Program Files (x86)\python\lib\site-packages\django\core\handlers\base.py", line 126, in _get_response
    response = wrapped_callback(request, *callback_args, **callback_kwargs)
  File "E:\project\ItTest\blackList\api\Interview.py", line 93, in download_doc
    _file = open(url, "rb")
FileNotFoundError: [Errno 2] No such file or directory: '0'
2018-08-10 13:32:35,295,10280,django.server,ERROR,basehttp.py:124,"GET /api/company/download?url=0 HTTP/1.1" 500 70987
2018-08-10 13:32:39,444,10280,django.request,ERROR,exception.py:118,Internal Server Error: /api/company/download
Traceback (most recent call last):
  File "D:\Program Files (x86)\python\lib\site-packages\django\core\handlers\exception.py", line 35, in inner
    response = get_response(request)
  File "D:\Program Files (x86)\python\lib\site-packages\django\core\handlers\base.py", line 128, in _get_response
    response = self.process_exception_by_middleware(e, request)
  File "D:\Program Files (x86)\python\lib\site-packages\django\core\handlers\base.py", line 126, in _get_response
    response = wrapped_callback(request, *callback_args, **callback_kwargs)
  File "E:\project\ItTest\blackList\api\Interview.py", line 93, in download_doc
    _file = open(url, "rb")
FileNotFoundError: [Errno 2] No such file or directory: '321'
2018-08-10 13:32:39,589,10280,django.server,ERROR,basehttp.py:124,"GET /api/company/download?url=321 HTTP/1.1" 500 71011
2018-08-10 14:01:52,894,10280,django.request,ERROR,exception.py:118,Internal Server Error: /api/company/download
Traceback (most recent call last):
  File "D:\Program Files (x86)\python\lib\site-packages\django\core\handlers\exception.py", line 35, in inner
    response = get_response(request)
  File "D:\Program Files (x86)\python\lib\site-packages\django\core\handlers\base.py", line 128, in _get_response
    response = self.process_exception_by_middleware(e, request)
  File "D:\Program Files (x86)\python\lib\site-packages\django\core\handlers\base.py", line 126, in _get_response
    response = wrapped_callback(request, *callback_args, **callback_kwargs)
  File "E:\project\ItTest\blackList\api\Interview.py", line 93, in download_doc
    _file = open(url, "rb")
FileNotFoundError: [Errno 2] No such file or directory: '321'
2018-08-10 14:01:53,002,10280,django.server,ERROR,basehttp.py:124,"GET /api/company/download?url=321 HTTP/1.1" 500 71011
2018-08-10 14:03:08,859,10280,django.request,ERROR,exception.py:118,Internal Server Error: /api/company/download
Traceback (most recent call last):
  File "D:\Program Files (x86)\python\lib\site-packages\django\core\handlers\exception.py", line 35, in inner
    response = get_response(request)
  File "D:\Program Files (x86)\python\lib\site-packages\django\core\handlers\base.py", line 128, in _get_response
    response = self.process_exception_by_middleware(e, request)
  File "D:\Program Files (x86)\python\lib\site-packages\django\core\handlers\base.py", line 126, in _get_response
    response = wrapped_callback(request, *callback_args, **callback_kwargs)
  File "E:\project\ItTest\blackList\api\Interview.py", line 93, in download_doc
    _file = open(url, "rb")
FileNotFoundError: [Errno 2] No such file or directory: '321'
2018-08-10 14:03:09,090,10280,django.server,ERROR,basehttp.py:124,"GET /api/company/download?url=321 HTTP/1.1" 500 71011
2018-08-10 14:16:28,932,18704,django.request,ERROR,exception.py:118,Internal Server Error: /api/company/download
Traceback (most recent call last):
  File "D:\Program Files (x86)\python\lib\site-packages\django\core\handlers\exception.py", line 35, in inner
    response = get_response(request)
  File "D:\Program Files (x86)\python\lib\site-packages\django\core\handlers\base.py", line 128, in _get_response
    response = self.process_exception_by_middleware(e, request)
  File "D:\Program Files (x86)\python\lib\site-packages\django\core\handlers\base.py", line 126, in _get_response
    response = wrapped_callback(request, *callback_args, **callback_kwargs)
  File "E:\project\ItTest\blackList\api\Interview.py", line 95, in download_doc
    response = StreamingHttpResponse(file_iterator(_file))
NameError: name '_file' is not defined
2018-08-10 14:16:29,404,18704,django.server,ERROR,basehttp.py:124,"GET /api/company/download?url=./data/1%E5%8F%B7%E5%BE%8B%E5%B8%88%E6%B5%8B%E8%AF%95%E7%82%B9%E6%A2%B3%E7%90%86.xlsx HTTP/1.1" 500 71884
2018-08-10 14:30:32,229,7288,django.request,ERROR,exception.py:118,Internal Server Error: /api/company/download
Traceback (most recent call last):
  File "D:\Program Files (x86)\python\lib\site-packages\django\core\handlers\exception.py", line 35, in inner
    response = get_response(request)
  File "D:\Program Files (x86)\python\lib\site-packages\django\core\handlers\base.py", line 128, in _get_response
    response = self.process_exception_by_middleware(e, request)
  File "D:\Program Files (x86)\python\lib\site-packages\django\core\handlers\base.py", line 126, in _get_response
    response = wrapped_callback(request, *callback_args, **callback_kwargs)
  File "E:\project\ItTest\blackList\api\Interview.py", line 95, in download_doc
    _file = open(url, "rb")
FileNotFoundError: [Errno 2] No such file or directory: '321'
2018-08-10 14:30:32,329,7288,django.server,ERROR,basehttp.py:124,"GET /api/company/download?url=321 HTTP/1.1" 500 71447
2018-08-14 16:42:11,644,8952,django.request,ERROR,exception.py:118,Internal Server Error: /api/company/feedView
Traceback (most recent call last):
  File "D:\Program Files (x86)\python\lib\site-packages\django\core\handlers\exception.py", line 35, in inner
    response = get_response(request)
  File "D:\Program Files (x86)\python\lib\site-packages\django\core\handlers\base.py", line 128, in _get_response
    response = self.process_exception_by_middleware(e, request)
  File "D:\Program Files (x86)\python\lib\site-packages\django\core\handlers\base.py", line 126, in _get_response
    response = wrapped_callback(request, *callback_args, **callback_kwargs)
  File "D:\Program Files (x86)\python\lib\site-packages\django\views\decorators\csrf.py", line 54, in wrapped_view
    return view_func(*args, **kwargs)
  File "D:\Program Files (x86)\python\lib\site-packages\django\views\generic\base.py", line 69, in view
    return self.dispatch(request, *args, **kwargs)
  File "D:\Program Files (x86)\python\lib\site-packages\rest_framework\views.py", line 489, in dispatch
    response = self.handle_exception(exc)
  File "D:\Program Files (x86)\python\lib\site-packages\rest_framework\views.py", line 451, in handle_exception
    self.raise_uncaught_exception(exc)
  File "D:\Program Files (x86)\python\lib\site-packages\rest_framework\views.py", line 486, in dispatch
    response = handler(request, *args, **kwargs)
  File "E:\project\ItTest\blackList\api\Interview.py", line 59, in post
    data["InterviewTime"] = datetime.strptime(data["InterviewTime"], "%Y-%m-%d %H:%M:%S")
  File "D:\Program Files (x86)\python\lib\_strptime.py", line 565, in _strptime_datetime
    tt, fraction = _strptime(data_string, format)
  File "D:\Program Files (x86)\python\lib\_strptime.py", line 362, in _strptime
    (data_string, format))
ValueError: time data '2018-08-13T16:00:00.000Z' does not match format '%Y-%m-%d %H:%M:%S'
2018-08-14 16:42:12,079,8952,django.server,ERROR,basehttp.py:124,"POST /api/company/feedView HTTP/1.1" 500 18273
2018-08-14 16:44:41,308,11068,django.request,ERROR,exception.py:118,Internal Server Error: /api/company/feedView
Traceback (most recent call last):
  File "D:\Program Files (x86)\python\lib\site-packages\django\core\handlers\exception.py", line 35, in inner
    response = get_response(request)
  File "D:\Program Files (x86)\python\lib\site-packages\django\core\handlers\base.py", line 128, in _get_response
    response = self.process_exception_by_middleware(e, request)
  File "D:\Program Files (x86)\python\lib\site-packages\django\core\handlers\base.py", line 126, in _get_response
    response = wrapped_callback(request, *callback_args, **callback_kwargs)
  File "D:\Program Files (x86)\python\lib\site-packages\django\views\decorators\csrf.py", line 54, in wrapped_view
    return view_func(*args, **kwargs)
  File "D:\Program Files (x86)\python\lib\site-packages\django\views\generic\base.py", line 69, in view
    return self.dispatch(request, *args, **kwargs)
  File "D:\Program Files (x86)\python\lib\site-packages\rest_framework\views.py", line 489, in dispatch
    response = self.handle_exception(exc)
  File "D:\Program Files (x86)\python\lib\site-packages\rest_framework\views.py", line 451, in handle_exception
    self.raise_uncaught_exception(exc)
  File "D:\Program Files (x86)\python\lib\site-packages\rest_framework\views.py", line 486, in dispatch
    response = handler(request, *args, **kwargs)
  File "E:\project\ItTest\blackList\api\Interview.py", line 60, in post
    data["InterviewTime"] = datetime.strptime(data["InterviewTime"], "%Y-%m-%d %H:%M:%S")
  File "D:\Program Files (x86)\python\lib\_strptime.py", line 565, in _strptime_datetime
    tt, fraction = _strptime(data_string, format)
  File "D:\Program Files (x86)\python\lib\_strptime.py", line 362, in _strptime
    (data_string, format))
ValueError: time data '2018-08-13T16:00:00.000Z' does not match format '%Y-%m-%d %H:%M:%S'
2018-08-14 16:44:42,126,11068,django.server,ERROR,basehttp.py:124,"POST /api/company/feedView HTTP/1.1" 500 18272
2018-08-14 16:46:12,105,8088,django.request,ERROR,exception.py:118,Internal Server Error: /api/company/feedView
Traceback (most recent call last):
  File "D:\Program Files (x86)\python\lib\site-packages\django\core\handlers\exception.py", line 35, in inner
    response = get_response(request)
  File "D:\Program Files (x86)\python\lib\site-packages\django\core\handlers\base.py", line 128, in _get_response
    response = self.process_exception_by_middleware(e, request)
  File "D:\Program Files (x86)\python\lib\site-packages\django\core\handlers\base.py", line 126, in _get_response
    response = wrapped_callback(request, *callback_args, **callback_kwargs)
  File "D:\Program Files (x86)\python\lib\site-packages\django\views\decorators\csrf.py", line 54, in wrapped_view
    return view_func(*args, **kwargs)
  File "D:\Program Files (x86)\python\lib\site-packages\django\views\generic\base.py", line 69, in view
    return self.dispatch(request, *args, **kwargs)
  File "D:\Program Files (x86)\python\lib\site-packages\rest_framework\views.py", line 489, in dispatch
    response = self.handle_exception(exc)
  File "D:\Program Files (x86)\python\lib\site-packages\rest_framework\views.py", line 451, in handle_exception
    self.raise_uncaught_exception(exc)
  File "D:\Program Files (x86)\python\lib\site-packages\rest_framework\views.py", line 486, in dispatch
    response = handler(request, *args, **kwargs)
  File "E:\project\ItTest\blackList\api\Interview.py", line 60, in post
    a = datetime.strptime(data["InterviewTime"], "%Y-%m-%d %H:%M:%S")
  File "D:\Program Files (x86)\python\lib\_strptime.py", line 565, in _strptime_datetime
    tt, fraction = _strptime(data_string, format)
  File "D:\Program Files (x86)\python\lib\_strptime.py", line 362, in _strptime
    (data_string, format))
ValueError: time data '2018-08-13T16:00:00.000Z' does not match format '%Y-%m-%d %H:%M:%S'
2018-08-14 16:46:12,868,8088,django.server,ERROR,basehttp.py:124,"POST /api/company/feedView HTTP/1.1" 500 18253
2018-08-14 16:47:01,926,17620,django.request,ERROR,exception.py:118,Internal Server Error: /api/company/feedView
Traceback (most recent call last):
  File "D:\Program Files (x86)\python\lib\site-packages\django\core\handlers\exception.py", line 35, in inner
    response = get_response(request)
  File "D:\Program Files (x86)\python\lib\site-packages\django\core\handlers\base.py", line 128, in _get_response
    response = self.process_exception_by_middleware(e, request)
  File "D:\Program Files (x86)\python\lib\site-packages\django\core\handlers\base.py", line 126, in _get_response
    response = wrapped_callback(request, *callback_args, **callback_kwargs)
  File "D:\Program Files (x86)\python\lib\site-packages\django\views\decorators\csrf.py", line 54, in wrapped_view
    return view_func(*args, **kwargs)
  File "D:\Program Files (x86)\python\lib\site-packages\django\views\generic\base.py", line 69, in view
    return self.dispatch(request, *args, **kwargs)
  File "D:\Program Files (x86)\python\lib\site-packages\rest_framework\views.py", line 489, in dispatch
    response = self.handle_exception(exc)
  File "D:\Program Files (x86)\python\lib\site-packages\rest_framework\views.py", line 451, in handle_exception
    self.raise_uncaught_exception(exc)
  File "D:\Program Files (x86)\python\lib\site-packages\rest_framework\views.py", line 486, in dispatch
    response = handler(request, *args, **kwargs)
  File "E:\project\ItTest\blackList\api\Interview.py", line 60, in post
    data["InterviewTime"] = datetime.strftime(data["InterviewTime"], "%Y-%m-%d %H:%M:%S")
TypeError: descriptor 'strftime' requires a 'datetime.date' object but received a 'str'
2018-08-14 16:47:02,625,17620,django.server,ERROR,basehttp.py:124,"POST /api/company/feedView HTTP/1.1" 500 18010
2018-08-14 16:49:15,159,11152,django.request,ERROR,exception.py:118,Internal Server Error: /api/company/feedView
Traceback (most recent call last):
  File "D:\Program Files (x86)\python\lib\site-packages\django\core\handlers\exception.py", line 35, in inner
    response = get_response(request)
  File "D:\Program Files (x86)\python\lib\site-packages\django\core\handlers\base.py", line 128, in _get_response
    response = self.process_exception_by_middleware(e, request)
  File "D:\Program Files (x86)\python\lib\site-packages\django\core\handlers\base.py", line 126, in _get_response
    response = wrapped_callback(request, *callback_args, **callback_kwargs)
  File "D:\Program Files (x86)\python\lib\site-packages\django\views\decorators\csrf.py", line 54, in wrapped_view
    return view_func(*args, **kwargs)
  File "D:\Program Files (x86)\python\lib\site-packages\django\views\generic\base.py", line 69, in view
    return self.dispatch(request, *args, **kwargs)
  File "D:\Program Files (x86)\python\lib\site-packages\rest_framework\views.py", line 489, in dispatch
    response = self.handle_exception(exc)
  File "D:\Program Files (x86)\python\lib\site-packages\rest_framework\views.py", line 451, in handle_exception
    self.raise_uncaught_exception(exc)
  File "D:\Program Files (x86)\python\lib\site-packages\rest_framework\views.py", line 486, in dispatch
    response = handler(request, *args, **kwargs)
  File "E:\project\ItTest\blackList\api\Interview.py", line 59, in post
    data["InterviewTime"] = datetime.strptime(data["InterviewTime"], "%Y-%m-%d %H:%M:%S")
  File "D:\Program Files (x86)\python\lib\_strptime.py", line 565, in _strptime_datetime
    tt, fraction = _strptime(data_string, format)
  File "D:\Program Files (x86)\python\lib\_strptime.py", line 362, in _strptime
    (data_string, format))
ValueError: time data '2018-08-13T16:00:00.000Z' does not match format '%Y-%m-%d %H:%M:%S'
2018-08-14 16:49:16,016,11152,django.server,ERROR,basehttp.py:124,"POST /api/company/feedView HTTP/1.1" 500 18276
2018-08-14 16:50:04,363,11152,django.request,ERROR,exception.py:118,Internal Server Error: /api/company/feedView
Traceback (most recent call last):
  File "D:\Program Files (x86)\python\lib\site-packages\django\core\handlers\exception.py", line 35, in inner
    response = get_response(request)
  File "D:\Program Files (x86)\python\lib\site-packages\django\core\handlers\base.py", line 128, in _get_response
    response = self.process_exception_by_middleware(e, request)
  File "D:\Program Files (x86)\python\lib\site-packages\django\core\handlers\base.py", line 126, in _get_response
    response = wrapped_callback(request, *callback_args, **callback_kwargs)
  File "D:\Program Files (x86)\python\lib\site-packages\django\views\decorators\csrf.py", line 54, in wrapped_view
    return view_func(*args, **kwargs)
  File "D:\Program Files (x86)\python\lib\site-packages\django\views\generic\base.py", line 69, in view
    return self.dispatch(request, *args, **kwargs)
  File "D:\Program Files (x86)\python\lib\site-packages\rest_framework\views.py", line 489, in dispatch
    response = self.handle_exception(exc)
  File "D:\Program Files (x86)\python\lib\site-packages\rest_framework\views.py", line 451, in handle_exception
    self.raise_uncaught_exception(exc)
  File "D:\Program Files (x86)\python\lib\site-packages\rest_framework\views.py", line 486, in dispatch
    response = handler(request, *args, **kwargs)
  File "E:\project\ItTest\blackList\api\Interview.py", line 59, in post
    data["InterviewTime"] = datetime.strptime(data["InterviewTime"], "%Y-%m-%d %H:%M:%S")
  File "D:\Program Files (x86)\python\lib\_strptime.py", line 565, in _strptime_datetime
    tt, fraction = _strptime(data_string, format)
  File "D:\Program Files (x86)\python\lib\_strptime.py", line 362, in _strptime
    (data_string, format))
ValueError: time data '2018-08-13T16:00:00.000Z' does not match format '%Y-%m-%d %H:%M:%S'
2018-08-14 16:50:04,441,11152,django.server,ERROR,basehttp.py:124,"POST /api/company/feedView HTTP/1.1" 500 18276
2018-08-14 16:50:54,416,11152,django.request,ERROR,exception.py:118,Internal Server Error: /api/company/feedView
Traceback (most recent call last):
  File "D:\Program Files (x86)\python\lib\site-packages\django\core\handlers\exception.py", line 35, in inner
    response = get_response(request)
  File "D:\Program Files (x86)\python\lib\site-packages\django\core\handlers\base.py", line 128, in _get_response
    response = self.process_exception_by_middleware(e, request)
  File "D:\Program Files (x86)\python\lib\site-packages\django\core\handlers\base.py", line 126, in _get_response
    response = wrapped_callback(request, *callback_args, **callback_kwargs)
  File "D:\Program Files (x86)\python\lib\site-packages\django\views\decorators\csrf.py", line 54, in wrapped_view
    return view_func(*args, **kwargs)
  File "D:\Program Files (x86)\python\lib\site-packages\django\views\generic\base.py", line 69, in view
    return self.dispatch(request, *args, **kwargs)
  File "D:\Program Files (x86)\python\lib\site-packages\rest_framework\views.py", line 489, in dispatch
    response = self.handle_exception(exc)
  File "D:\Program Files (x86)\python\lib\site-packages\rest_framework\views.py", line 451, in handle_exception
    self.raise_uncaught_exception(exc)
  File "D:\Program Files (x86)\python\lib\site-packages\rest_framework\views.py", line 486, in dispatch
    response = handler(request, *args, **kwargs)
  File "E:\project\ItTest\blackList\api\Interview.py", line 59, in post
    data["InterviewTime"] = datetime.strptime(data["InterviewTime"], "%Y-%m-%d %H:%M:%S")
  File "D:\Program Files (x86)\python\lib\_strptime.py", line 565, in _strptime_datetime
    tt, fraction = _strptime(data_string, format)
  File "D:\Program Files (x86)\python\lib\_strptime.py", line 362, in _strptime
    (data_string, format))
ValueError: time data '2018-08-13T16:00:00.000Z' does not match format '%Y-%m-%d %H:%M:%S'
2018-08-14 16:50:54,492,11152,django.server,ERROR,basehttp.py:124,"POST /api/company/feedView HTTP/1.1" 500 18273
2018-08-14 16:55:43,616,2220,django.request,ERROR,exception.py:118,Internal Server Error: /api/company/feedView
Traceback (most recent call last):
  File "D:\Program Files (x86)\python\lib\site-packages\django\core\handlers\exception.py", line 35, in inner
    response = get_response(request)
  File "D:\Program Files (x86)\python\lib\site-packages\django\core\handlers\base.py", line 128, in _get_response
    response = self.process_exception_by_middleware(e, request)
  File "D:\Program Files (x86)\python\lib\site-packages\django\core\handlers\base.py", line 126, in _get_response
    response = wrapped_callback(request, *callback_args, **callback_kwargs)
  File "D:\Program Files (x86)\python\lib\site-packages\django\views\decorators\csrf.py", line 54, in wrapped_view
    return view_func(*args, **kwargs)
  File "D:\Program Files (x86)\python\lib\site-packages\django\views\generic\base.py", line 69, in view
    return self.dispatch(request, *args, **kwargs)
  File "D:\Program Files (x86)\python\lib\site-packages\rest_framework\views.py", line 489, in dispatch
    response = self.handle_exception(exc)
  File "D:\Program Files (x86)\python\lib\site-packages\rest_framework\views.py", line 451, in handle_exception
    self.raise_uncaught_exception(exc)
  File "D:\Program Files (x86)\python\lib\site-packages\rest_framework\views.py", line 486, in dispatch
    response = handler(request, *args, **kwargs)
  File "E:\project\ItTest\blackList\api\Interview.py", line 59, in post
    data["InterviewTime"] = datetime.strptime(data["InterviewTime"], "%Y-%m-%dT%H:%M:%S")
  File "D:\Program Files (x86)\python\lib\_strptime.py", line 565, in _strptime_datetime
    tt, fraction = _strptime(data_string, format)
  File "D:\Program Files (x86)\python\lib\_strptime.py", line 365, in _strptime
    data_string[found.end():])
ValueError: unconverted data remains: .000Z
2018-08-14 16:55:44,316,2220,django.server,ERROR,basehttp.py:124,"POST /api/company/feedView HTTP/1.1" 500 18184
2018-08-14 16:58:35,243,13296,django.request,ERROR,exception.py:118,Internal Server Error: /api/company/feedView
Traceback (most recent call last):
  File "D:\Program Files (x86)\python\lib\site-packages\django\core\handlers\exception.py", line 35, in inner
    response = get_response(request)
  File "D:\Program Files (x86)\python\lib\site-packages\django\core\handlers\base.py", line 128, in _get_response
    response = self.process_exception_by_middleware(e, request)
  File "D:\Program Files (x86)\python\lib\site-packages\django\core\handlers\base.py", line 126, in _get_response
    response = wrapped_callback(request, *callback_args, **callback_kwargs)
  File "D:\Program Files (x86)\python\lib\site-packages\django\views\decorators\csrf.py", line 54, in wrapped_view
    return view_func(*args, **kwargs)
  File "D:\Program Files (x86)\python\lib\site-packages\django\views\generic\base.py", line 69, in view
    return self.dispatch(request, *args, **kwargs)
  File "D:\Program Files (x86)\python\lib\site-packages\rest_framework\views.py", line 489, in dispatch
    response = self.handle_exception(exc)
  File "D:\Program Files (x86)\python\lib\site-packages\rest_framework\views.py", line 451, in handle_exception
    self.raise_uncaught_exception(exc)
  File "D:\Program Files (x86)\python\lib\site-packages\rest_framework\views.py", line 486, in dispatch
    response = handler(request, *args, **kwargs)
  File "E:\project\ItTest\blackList\api\Interview.py", line 60, in post
    data["InterviewTime"] = datetime.strptime(data["InterviewTime"], "%Y-%m-%dT%H:%M:%S.%Z")
  File "D:\Program Files (x86)\python\lib\_strptime.py", line 565, in _strptime_datetime
    tt, fraction = _strptime(data_string, format)
  File "D:\Program Files (x86)\python\lib\_strptime.py", line 362, in _strptime
    (data_string, format))
ValueError: time data '2018-08-13T16:00:00.000Z' does not match format '%Y-%m-%dT%H:%M:%S.%Z'
2018-08-14 16:58:36,078,13296,django.server,ERROR,basehttp.py:124,"POST /api/company/feedView HTTP/1.1" 500 18282
2018-08-14 17:00:50,222,12128,django.request,ERROR,exception.py:118,Internal Server Error: /api/company/feedView
Traceback (most recent call last):
  File "D:\Program Files (x86)\python\lib\site-packages\django\core\handlers\exception.py", line 35, in inner
    response = get_response(request)
  File "D:\Program Files (x86)\python\lib\site-packages\django\core\handlers\base.py", line 128, in _get_response
    response = self.process_exception_by_middleware(e, request)
  File "D:\Program Files (x86)\python\lib\site-packages\django\core\handlers\base.py", line 126, in _get_response
    response = wrapped_callback(request, *callback_args, **callback_kwargs)
  File "D:\Program Files (x86)\python\lib\site-packages\django\views\decorators\csrf.py", line 54, in wrapped_view
    return view_func(*args, **kwargs)
  File "D:\Program Files (x86)\python\lib\site-packages\django\views\generic\base.py", line 69, in view
    return self.dispatch(request, *args, **kwargs)
  File "D:\Program Files (x86)\python\lib\site-packages\rest_framework\views.py", line 489, in dispatch
    response = self.handle_exception(exc)
  File "D:\Program Files (x86)\python\lib\site-packages\rest_framework\views.py", line 451, in handle_exception
    self.raise_uncaught_exception(exc)
  File "D:\Program Files (x86)\python\lib\site-packages\rest_framework\views.py", line 486, in dispatch
    response = handler(request, *args, **kwargs)
  File "E:\project\ItTest\blackList\api\Interview.py", line 60, in post
    data["InterviewTime"] = datetime.strptime(data["InterviewTime"].split(".")[:-1], "%Y-%m-%dT%H:%M:%S")
TypeError: strptime() argument 1 must be str, not list
2018-08-14 17:00:50,991,12128,django.server,ERROR,basehttp.py:124,"POST /api/company/feedView HTTP/1.1" 500 17960
2018-08-14 17:25:00,309,16996,django.request,ERROR,exception.py:118,Internal Server Error: /api/company/feedView
Traceback (most recent call last):
  File "D:\Program Files (x86)\python\lib\site-packages\django\core\handlers\exception.py", line 35, in inner
    response = get_response(request)
  File "D:\Program Files (x86)\python\lib\site-packages\django\core\handlers\base.py", line 128, in _get_response
    response = self.process_exception_by_middleware(e, request)
  File "D:\Program Files (x86)\python\lib\site-packages\django\core\handlers\base.py", line 126, in _get_response
    response = wrapped_callback(request, *callback_args, **callback_kwargs)
  File "D:\Program Files (x86)\python\lib\site-packages\django\views\decorators\csrf.py", line 54, in wrapped_view
    return view_func(*args, **kwargs)
  File "D:\Program Files (x86)\python\lib\site-packages\django\views\generic\base.py", line 69, in view
    return self.dispatch(request, *args, **kwargs)
  File "D:\Program Files (x86)\python\lib\site-packages\rest_framework\views.py", line 489, in dispatch
    response = self.handle_exception(exc)
  File "D:\Program Files (x86)\python\lib\site-packages\rest_framework\views.py", line 451, in handle_exception
    self.raise_uncaught_exception(exc)
  File "D:\Program Files (x86)\python\lib\site-packages\rest_framework\views.py", line 486, in dispatch
    response = handler(request, *args, **kwargs)
  File "E:\project\ItTest\blackList\api\Interview.py", line 58, in post
    data["InterviewTime"] = datetime.strptime(data["InterviewTime"], "%Y-%m-%d")
  File "D:\Program Files (x86)\python\lib\_strptime.py", line 565, in _strptime_datetime
    tt, fraction = _strptime(data_string, format)
  File "D:\Program Files (x86)\python\lib\_strptime.py", line 365, in _strptime
    data_string[found.end():])
ValueError: unconverted data remains:  00:00:00
2018-08-14 17:25:00,721,16996,django.server,ERROR,basehttp.py:124,"POST /api/company/feedView HTTP/1.1" 500 18183
2018-08-14 17:39:50,847,9304,django.request,ERROR,exception.py:118,Internal Server Error: /api/company/feedView
Traceback (most recent call last):
  File "D:\Program Files (x86)\python\lib\site-packages\django\core\handlers\exception.py", line 35, in inner
    response = get_response(request)
  File "D:\Program Files (x86)\python\lib\site-packages\django\core\handlers\base.py", line 128, in _get_response
    response = self.process_exception_by_middleware(e, request)
  File "D:\Program Files (x86)\python\lib\site-packages\django\core\handlers\base.py", line 126, in _get_response
    response = wrapped_callback(request, *callback_args, **callback_kwargs)
  File "D:\Program Files (x86)\python\lib\site-packages\django\views\decorators\csrf.py", line 54, in wrapped_view
    return view_func(*args, **kwargs)
  File "D:\Program Files (x86)\python\lib\site-packages\django\views\generic\base.py", line 69, in view
    return self.dispatch(request, *args, **kwargs)
  File "D:\Program Files (x86)\python\lib\site-packages\rest_framework\views.py", line 489, in dispatch
    response = self.handle_exception(exc)
  File "D:\Program Files (x86)\python\lib\site-packages\rest_framework\views.py", line 451, in handle_exception
    self.raise_uncaught_exception(exc)
  File "D:\Program Files (x86)\python\lib\site-packages\rest_framework\views.py", line 486, in dispatch
    response = handler(request, *args, **kwargs)
  File "E:\project\ItTest\blackList\api\Interview.py", line 58, in post
    data["InterviewTime"] = datetime.strptime(data["InterviewTime"], "%Y-%m-%d %H:%M:%S")
  File "D:\Program Files (x86)\python\lib\_strptime.py", line 565, in _strptime_datetime
    tt, fraction = _strptime(data_string, format)
  File "D:\Program Files (x86)\python\lib\_strptime.py", line 362, in _strptime
    (data_string, format))
ValueError: time data '2018-08-14' does not match format '%Y-%m-%d %H:%M:%S'
2018-08-14 17:39:51,200,9304,django.server,ERROR,basehttp.py:124,"POST /api/company/feedView HTTP/1.1" 500 18244
2018-08-14 18:07:28,820,2520,django.request,ERROR,exception.py:118,Internal Server Error: /api/company/feedView
Traceback (most recent call last):
  File "D:\Program Files (x86)\python\lib\site-packages\django\core\handlers\exception.py", line 35, in inner
    response = get_response(request)
  File "D:\Program Files (x86)\python\lib\site-packages\django\core\handlers\base.py", line 128, in _get_response
    response = self.process_exception_by_middleware(e, request)
  File "D:\Program Files (x86)\python\lib\site-packages\django\core\handlers\base.py", line 126, in _get_response
    response = wrapped_callback(request, *callback_args, **callback_kwargs)
  File "D:\Program Files (x86)\python\lib\site-packages\django\views\decorators\csrf.py", line 54, in wrapped_view
    return view_func(*args, **kwargs)
  File "D:\Program Files (x86)\python\lib\site-packages\django\views\generic\base.py", line 69, in view
    return self.dispatch(request, *args, **kwargs)
  File "D:\Program Files (x86)\python\lib\site-packages\rest_framework\views.py", line 489, in dispatch
    response = self.handle_exception(exc)
  File "D:\Program Files (x86)\python\lib\site-packages\rest_framework\views.py", line 451, in handle_exception
    self.raise_uncaught_exception(exc)
  File "D:\Program Files (x86)\python\lib\site-packages\rest_framework\views.py", line 486, in dispatch
    response = handler(request, *args, **kwargs)
  File "E:\project\ItTest\blackList\api\Interview.py", line 65, in post
    welfare='', InterviewSummaryToPerson='').save()
  File "D:\Program Files (x86)\python\lib\site-packages\django\db\models\base.py", line 495, in __init__
    raise TypeError("'%s' is an invalid keyword argument for this function" % kwarg)
TypeError: 'InterviewPos' is an invalid keyword argument for this function
2018-08-14 18:07:29,117,2520,django.server,ERROR,basehttp.py:124,"POST /api/company/feedView HTTP/1.1" 500 18152
2018-08-14 18:12:25,345,6700,django.request,ERROR,exception.py:118,Internal Server Error: /api/company/feedView
Traceback (most recent call last):
  File "D:\Program Files (x86)\python\lib\site-packages\django\core\handlers\exception.py", line 35, in inner
    response = get_response(request)
  File "D:\Program Files (x86)\python\lib\site-packages\django\core\handlers\base.py", line 128, in _get_response
    response = self.process_exception_by_middleware(e, request)
  File "D:\Program Files (x86)\python\lib\site-packages\django\core\handlers\base.py", line 126, in _get_response
    response = wrapped_callback(request, *callback_args, **callback_kwargs)
  File "D:\Program Files (x86)\python\lib\site-packages\django\views\decorators\csrf.py", line 54, in wrapped_view
    return view_func(*args, **kwargs)
  File "D:\Program Files (x86)\python\lib\site-packages\django\views\generic\base.py", line 69, in view
    return self.dispatch(request, *args, **kwargs)
  File "D:\Program Files (x86)\python\lib\site-packages\rest_framework\views.py", line 489, in dispatch
    response = self.handle_exception(exc)
  File "D:\Program Files (x86)\python\lib\site-packages\rest_framework\views.py", line 451, in handle_exception
    self.raise_uncaught_exception(exc)
  File "D:\Program Files (x86)\python\lib\site-packages\rest_framework\views.py", line 486, in dispatch
    response = handler(request, *args, **kwargs)
  File "E:\project\ItTest\blackList\api\Interview.py", line 63, in post
    InterviewTime=datetime.datetime(2018, 8, 14, 18, 9, 58, 403868),
AttributeError: type object 'datetime.datetime' has no attribute 'datetime'
2018-08-14 18:12:25,760,6700,django.server,ERROR,basehttp.py:124,"POST /api/company/feedView HTTP/1.1" 500 17974
2018-08-14 18:25:10,720,18764,django.request,ERROR,exception.py:118,Internal Server Error: /api/company/updata
Traceback (most recent call last):
  File "D:\Program Files (x86)\python\lib\site-packages\django\core\handlers\exception.py", line 35, in inner
    response = get_response(request)
  File "D:\Program Files (x86)\python\lib\site-packages\django\core\handlers\base.py", line 128, in _get_response
    response = self.process_exception_by_middleware(e, request)
  File "D:\Program Files (x86)\python\lib\site-packages\django\core\handlers\base.py", line 126, in _get_response
    response = wrapped_callback(request, *callback_args, **callback_kwargs)
  File "D:\Program Files (x86)\python\lib\site-packages\django\views\decorators\csrf.py", line 54, in wrapped_view
    return view_func(*args, **kwargs)
  File "D:\Program Files (x86)\python\lib\site-packages\django\views\generic\base.py", line 69, in view
    return self.dispatch(request, *args, **kwargs)
  File "D:\Program Files (x86)\python\lib\site-packages\rest_framework\views.py", line 489, in dispatch
    response = self.handle_exception(exc)
  File "D:\Program Files (x86)\python\lib\site-packages\rest_framework\views.py", line 451, in handle_exception
    self.raise_uncaught_exception(exc)
  File "D:\Program Files (x86)\python\lib\site-packages\rest_framework\views.py", line 486, in dispatch
    response = handler(request, *args, **kwargs)
  File "E:\project\ItTest\blackList\api\Interview.py", line 82, in post
    file_to_save = open(os.path.join("data", _file.name), "wb+")
FileNotFoundError: [Errno 2] No such file or directory: 'data\\HTMLTestRunner_PY3-master.zip'
2018-08-14 18:25:11,632,18764,django.server,ERROR,basehttp.py:124,"POST /api/company/updata HTTP/1.1" 500 18064
2018-08-14 18:26:21,857,18764,django.request,ERROR,exception.py:118,Internal Server Error: /api/company/updata
Traceback (most recent call last):
  File "D:\Program Files (x86)\python\lib\site-packages\django\core\handlers\exception.py", line 35, in inner
    response = get_response(request)
  File "D:\Program Files (x86)\python\lib\site-packages\django\core\handlers\base.py", line 128, in _get_response
    response = self.process_exception_by_middleware(e, request)
  File "D:\Program Files (x86)\python\lib\site-packages\django\core\handlers\base.py", line 126, in _get_response
    response = wrapped_callback(request, *callback_args, **callback_kwargs)
  File "D:\Program Files (x86)\python\lib\site-packages\django\views\decorators\csrf.py", line 54, in wrapped_view
    return view_func(*args, **kwargs)
  File "D:\Program Files (x86)\python\lib\site-packages\django\views\generic\base.py", line 69, in view
    return self.dispatch(request, *args, **kwargs)
  File "D:\Program Files (x86)\python\lib\site-packages\rest_framework\views.py", line 489, in dispatch
    response = self.handle_exception(exc)
  File "D:\Program Files (x86)\python\lib\site-packages\rest_framework\views.py", line 451, in handle_exception
    self.raise_uncaught_exception(exc)
  File "D:\Program Files (x86)\python\lib\site-packages\rest_framework\views.py", line 486, in dispatch
    response = handler(request, *args, **kwargs)
  File "E:\project\ItTest\blackList\api\Interview.py", line 82, in post
    file_to_save = open(os.path.join("data", _file.name), "wb+")
FileNotFoundError: [Errno 2] No such file or directory: 'data\\HTMLTestRunner_PY3-master.zip'
2018-08-14 18:26:22,089,18764,django.server,ERROR,basehttp.py:124,"POST /api/company/updata HTTP/1.1" 500 18064
2018-08-14 18:26:41,814,18764,django.request,ERROR,exception.py:118,Internal Server Error: /api/company/updata
Traceback (most recent call last):
  File "D:\Program Files (x86)\python\lib\site-packages\django\core\handlers\exception.py", line 35, in inner
    response = get_response(request)
  File "D:\Program Files (x86)\python\lib\site-packages\django\core\handlers\base.py", line 128, in _get_response
    response = self.process_exception_by_middleware(e, request)
  File "D:\Program Files (x86)\python\lib\site-packages\django\core\handlers\base.py", line 126, in _get_response
    response = wrapped_callback(request, *callback_args, **callback_kwargs)
  File "D:\Program Files (x86)\python\lib\site-packages\django\views\decorators\csrf.py", line 54, in wrapped_view
    return view_func(*args, **kwargs)
  File "D:\Program Files (x86)\python\lib\site-packages\django\views\generic\base.py", line 69, in view
    return self.dispatch(request, *args, **kwargs)
  File "D:\Program Files (x86)\python\lib\site-packages\rest_framework\views.py", line 489, in dispatch
    response = self.handle_exception(exc)
  File "D:\Program Files (x86)\python\lib\site-packages\rest_framework\views.py", line 451, in handle_exception
    self.raise_uncaught_exception(exc)
  File "D:\Program Files (x86)\python\lib\site-packages\rest_framework\views.py", line 486, in dispatch
    response = handler(request, *args, **kwargs)
  File "E:\project\ItTest\blackList\api\Interview.py", line 82, in post
    file_to_save = open(os.path.join("data", _file.name), "wb+")
FileNotFoundError: [Errno 2] No such file or directory: 'data\\HTMLTestRunner_PY3-master.zip'
2018-08-14 18:26:41,893,18764,django.server,ERROR,basehttp.py:124,"POST /api/company/updata HTTP/1.1" 500 18064
2018-08-14 18:27:20,203,9116,django.request,ERROR,exception.py:118,Internal Server Error: /api/company/updata
Traceback (most recent call last):
  File "D:\Program Files (x86)\python\lib\site-packages\django\core\handlers\exception.py", line 35, in inner
    response = get_response(request)
  File "D:\Program Files (x86)\python\lib\site-packages\django\core\handlers\base.py", line 128, in _get_response
    response = self.process_exception_by_middleware(e, request)
  File "D:\Program Files (x86)\python\lib\site-packages\django\core\handlers\base.py", line 126, in _get_response
    response = wrapped_callback(request, *callback_args, **callback_kwargs)
  File "D:\Program Files (x86)\python\lib\site-packages\django\views\decorators\csrf.py", line 54, in wrapped_view
    return view_func(*args, **kwargs)
  File "D:\Program Files (x86)\python\lib\site-packages\django\views\generic\base.py", line 69, in view
    return self.dispatch(request, *args, **kwargs)
  File "D:\Program Files (x86)\python\lib\site-packages\rest_framework\views.py", line 489, in dispatch
    response = self.handle_exception(exc)
  File "D:\Program Files (x86)\python\lib\site-packages\rest_framework\views.py", line 451, in handle_exception
    self.raise_uncaught_exception(exc)
  File "D:\Program Files (x86)\python\lib\site-packages\rest_framework\views.py", line 486, in dispatch
    response = handler(request, *args, **kwargs)
  File "E:\project\ItTest\blackList\api\Interview.py", line 82, in post
    file_to_save = open(os.path.join("./data", _file.name), "wb+")
FileNotFoundError: [Errno 2] No such file or directory: './data\\HTMLTestRunner_PY3-master.zip'
2018-08-14 18:27:20,604,9116,django.server,ERROR,basehttp.py:124,"POST /api/company/updata HTTP/1.1" 500 18070
2018-08-23 16:03:23,130,4232,django.request,ERROR,exception.py:118,Internal Server Error: /api/company/feedView
Traceback (most recent call last):
  File "D:\Program Files (x86)\python\lib\site-packages\django\core\handlers\exception.py", line 35, in inner
    response = get_response(request)
  File "D:\Program Files (x86)\python\lib\site-packages\django\core\handlers\base.py", line 128, in _get_response
    response = self.process_exception_by_middleware(e, request)
  File "D:\Program Files (x86)\python\lib\site-packages\django\core\handlers\base.py", line 126, in _get_response
    response = wrapped_callback(request, *callback_args, **callback_kwargs)
  File "D:\Program Files (x86)\python\lib\site-packages\django\views\decorators\csrf.py", line 54, in wrapped_view
    return view_func(*args, **kwargs)
  File "D:\Program Files (x86)\python\lib\site-packages\django\views\generic\base.py", line 69, in view
    return self.dispatch(request, *args, **kwargs)
  File "D:\Program Files (x86)\python\lib\site-packages\rest_framework\views.py", line 489, in dispatch
    response = self.handle_exception(exc)
  File "D:\Program Files (x86)\python\lib\site-packages\rest_framework\views.py", line 451, in handle_exception
    self.raise_uncaught_exception(exc)
  File "D:\Program Files (x86)\python\lib\site-packages\rest_framework\views.py", line 486, in dispatch
    response = handler(request, *args, **kwargs)
  File "E:\project\ItTest\blackList\api\Interview.py", line 58, in post
    data["InterviewTime"] = datetime.strptime(data["InterviewTime"], "%Y-%m-%d %H:%M:%S")
  File "D:\Program Files (x86)\python\lib\_strptime.py", line 565, in _strptime_datetime
    tt, fraction = _strptime(data_string, format)
  File "D:\Program Files (x86)\python\lib\_strptime.py", line 362, in _strptime
    (data_string, format))
ValueError: time data '2018-08-22T16:00:00.000Z' does not match format '%Y-%m-%d %H:%M:%S'
2018-08-23 16:03:23,738,4232,django.server,ERROR,basehttp.py:124,"POST /api/company/feedView HTTP/1.1" 500 18272
2018-08-23 16:18:46,115,4892,django.request,ERROR,exception.py:118,Internal Server Error: /api/company/feedView
Traceback (most recent call last):
  File "D:\Program Files (x86)\python\lib\site-packages\django\core\handlers\exception.py", line 35, in inner
    response = get_response(request)
  File "D:\Program Files (x86)\python\lib\site-packages\django\core\handlers\base.py", line 128, in _get_response
    response = self.process_exception_by_middleware(e, request)
  File "D:\Program Files (x86)\python\lib\site-packages\django\core\handlers\base.py", line 126, in _get_response
    response = wrapped_callback(request, *callback_args, **callback_kwargs)
  File "D:\Program Files (x86)\python\lib\site-packages\django\views\decorators\csrf.py", line 54, in wrapped_view
    return view_func(*args, **kwargs)
  File "D:\Program Files (x86)\python\lib\site-packages\django\views\generic\base.py", line 69, in view
    return self.dispatch(request, *args, **kwargs)
  File "D:\Program Files (x86)\python\lib\site-packages\rest_framework\views.py", line 489, in dispatch
    response = self.handle_exception(exc)
  File "D:\Program Files (x86)\python\lib\site-packages\rest_framework\views.py", line 451, in handle_exception
    self.raise_uncaught_exception(exc)
  File "D:\Program Files (x86)\python\lib\site-packages\rest_framework\views.py", line 486, in dispatch
    response = handler(request, *args, **kwargs)
  File "E:\project\ItTest\blackList\api\Interview.py", line 58, in post
    data["InterviewTime"] = datetime.strptime(data["InterviewTime"], "%Y-%m-%d %H:%M:%S")
  File "D:\Program Files (x86)\python\lib\_strptime.py", line 565, in _strptime_datetime
    tt, fraction = _strptime(data_string, format)
  File "D:\Program Files (x86)\python\lib\_strptime.py", line 362, in _strptime
    (data_string, format))
ValueError: time data '2018-08-22T16:00:00.000Z' does not match format '%Y-%m-%d %H:%M:%S'
2018-08-23 16:18:46,546,4892,django.server,ERROR,basehttp.py:124,"POST /api/company/feedView HTTP/1.1" 500 18272
2018-12-29 16:27:00,522,13028,django.request,ERROR,exception.py:118,Internal Server Error: /api/test/TestApi
Traceback (most recent call last):
  File "C:\Users\lt\AppData\Local\Programs\Python\Python37\lib\site-packages\django\core\handlers\exception.py", line 35, in inner
    response = get_response(request)
  File "C:\Users\lt\AppData\Local\Programs\Python\Python37\lib\site-packages\django\core\handlers\base.py", line 128, in _get_response
    response = self.process_exception_by_middleware(e, request)
  File "C:\Users\lt\AppData\Local\Programs\Python\Python37\lib\site-packages\django\core\handlers\base.py", line 126, in _get_response
    response = wrapped_callback(request, *callback_args, **callback_kwargs)
  File "C:\Users\lt\AppData\Local\Programs\Python\Python37\lib\site-packages\django\views\decorators\csrf.py", line 54, in wrapped_view
    return view_func(*args, **kwargs)
  File "C:\Users\lt\AppData\Local\Programs\Python\Python37\lib\site-packages\django\views\generic\base.py", line 69, in view
    return self.dispatch(request, *args, **kwargs)
  File "C:\Users\lt\AppData\Local\Programs\Python\Python37\lib\site-packages\rest_framework\views.py", line 494, in dispatch
    response = self.handle_exception(exc)
  File "C:\Users\lt\AppData\Local\Programs\Python\Python37\lib\site-packages\rest_framework\views.py", line 454, in handle_exception
    self.raise_uncaught_exception(exc)
  File "C:\Users\lt\AppData\Local\Programs\Python\Python37\lib\site-packages\rest_framework\views.py", line 491, in dispatch
    response = handler(request, *args, **kwargs)
  File "D:\project\ItTest\blackList\api\TestApi.py", line 46, in delete
    print(value.decode("utf-8"))
AttributeError: 'str' object has no attribute 'decode'
2018-12-29 16:28:31,167,20956,django.request,ERROR,exception.py:118,Internal Server Error: /api/test/TestApi
Traceback (most recent call last):
  File "C:\Users\lt\AppData\Local\Programs\Python\Python37\lib\urllib\parse.py", line 858, in urlencode
    raise TypeError
TypeError

During handling of the above exception, another exception occurred:

Traceback (most recent call last):
  File "C:\Users\lt\AppData\Local\Programs\Python\Python37\lib\site-packages\django\core\handlers\exception.py", line 35, in inner
    response = get_response(request)
  File "C:\Users\lt\AppData\Local\Programs\Python\Python37\lib\site-packages\django\core\handlers\base.py", line 128, in _get_response
    response = self.process_exception_by_middleware(e, request)
  File "C:\Users\lt\AppData\Local\Programs\Python\Python37\lib\site-packages\django\core\handlers\base.py", line 126, in _get_response
    response = wrapped_callback(request, *callback_args, **callback_kwargs)
  File "C:\Users\lt\AppData\Local\Programs\Python\Python37\lib\site-packages\django\views\decorators\csrf.py", line 54, in wrapped_view
    return view_func(*args, **kwargs)
  File "C:\Users\lt\AppData\Local\Programs\Python\Python37\lib\site-packages\django\views\generic\base.py", line 69, in view
    return self.dispatch(request, *args, **kwargs)
  File "C:\Users\lt\AppData\Local\Programs\Python\Python37\lib\site-packages\rest_framework\views.py", line 494, in dispatch
    response = self.handle_exception(exc)
  File "C:\Users\lt\AppData\Local\Programs\Python\Python37\lib\site-packages\rest_framework\views.py", line 454, in handle_exception
    self.raise_uncaught_exception(exc)
  File "C:\Users\lt\AppData\Local\Programs\Python\Python37\lib\site-packages\rest_framework\views.py", line 491, in dispatch
    response = handler(request, *args, **kwargs)
  File "D:\project\ItTest\blackList\api\TestApi.py", line 48, in delete
    print(urllib.parse.urlencode(value))
  File "C:\Users\lt\AppData\Local\Programs\Python\Python37\lib\urllib\parse.py", line 866, in urlencode
    "or mapping object").with_traceback(tb)
  File "C:\Users\lt\AppData\Local\Programs\Python\Python37\lib\urllib\parse.py", line 858, in urlencode
    raise TypeError
TypeError: not a valid non-string sequence or mapping object
2019-05-15 15:38:11,370,1012,django.request,ERROR,exception.py:118,Internal Server Error: /docs/
Traceback (most recent call last):
  File "/Library/Frameworks/Python.framework/Versions/3.7/lib/python3.7/site-packages/django/core/handlers/exception.py", line 35, in inner
    response = get_response(request)
  File "/Library/Frameworks/Python.framework/Versions/3.7/lib/python3.7/site-packages/django/core/handlers/base.py", line 158, in _get_response
    response = self.process_exception_by_middleware(e, request)
  File "/Library/Frameworks/Python.framework/Versions/3.7/lib/python3.7/site-packages/django/core/handlers/base.py", line 156, in _get_response
    response = response.render()
  File "/Library/Frameworks/Python.framework/Versions/3.7/lib/python3.7/site-packages/django/template/response.py", line 106, in render
    self.content = self.rendered_content
  File "/Library/Frameworks/Python.framework/Versions/3.7/lib/python3.7/site-packages/rest_framework/response.py", line 72, in rendered_content
    ret = renderer.render(self.data, accepted_media_type, context)
  File "/Library/Frameworks/Python.framework/Versions/3.7/lib/python3.7/site-packages/rest_framework_swagger/renderers.py", line 59, in render
    renderer_context
  File "/Library/Frameworks/Python.framework/Versions/3.7/lib/python3.7/site-packages/django/shortcuts.py", line 36, in render
    content = loader.render_to_string(template_name, context, request, using=using)
  File "/Library/Frameworks/Python.framework/Versions/3.7/lib/python3.7/site-packages/django/template/loader.py", line 61, in render_to_string
    template = get_template(template_name, using=using)
  File "/Library/Frameworks/Python.framework/Versions/3.7/lib/python3.7/site-packages/django/template/loader.py", line 19, in get_template
    raise TemplateDoesNotExist(template_name, chain=chain)
django.template.exceptions.TemplateDoesNotExist: rest_framework_swagger/index.html
2019-05-15 15:38:11,505,1012,django.server,ERROR,basehttp.py:124,"GET /docs/ HTTP/1.1" 500 93111
2019-05-15 15:38:25,022,1012,django.request,ERROR,exception.py:118,Internal Server Error: /docs/
Traceback (most recent call last):
  File "/Library/Frameworks/Python.framework/Versions/3.7/lib/python3.7/site-packages/django/core/handlers/exception.py", line 35, in inner
    response = get_response(request)
  File "/Library/Frameworks/Python.framework/Versions/3.7/lib/python3.7/site-packages/django/core/handlers/base.py", line 158, in _get_response
    response = self.process_exception_by_middleware(e, request)
  File "/Library/Frameworks/Python.framework/Versions/3.7/lib/python3.7/site-packages/django/core/handlers/base.py", line 156, in _get_response
    response = response.render()
  File "/Library/Frameworks/Python.framework/Versions/3.7/lib/python3.7/site-packages/django/template/response.py", line 106, in render
    self.content = self.rendered_content
  File "/Library/Frameworks/Python.framework/Versions/3.7/lib/python3.7/site-packages/rest_framework/response.py", line 72, in rendered_content
    ret = renderer.render(self.data, accepted_media_type, context)
  File "/Library/Frameworks/Python.framework/Versions/3.7/lib/python3.7/site-packages/rest_framework_swagger/renderers.py", line 59, in render
    renderer_context
  File "/Library/Frameworks/Python.framework/Versions/3.7/lib/python3.7/site-packages/django/shortcuts.py", line 36, in render
    content = loader.render_to_string(template_name, context, request, using=using)
  File "/Library/Frameworks/Python.framework/Versions/3.7/lib/python3.7/site-packages/django/template/loader.py", line 61, in render_to_string
    template = get_template(template_name, using=using)
  File "/Library/Frameworks/Python.framework/Versions/3.7/lib/python3.7/site-packages/django/template/loader.py", line 19, in get_template
    raise TemplateDoesNotExist(template_name, chain=chain)
django.template.exceptions.TemplateDoesNotExist: rest_framework_swagger/index.html
2019-05-15 15:38:25,081,1012,django.server,ERROR,basehttp.py:124,"GET /docs/ HTTP/1.1" 500 93246
2019-05-15 15:39:01,302,1028,django.request,ERROR,exception.py:118,Internal Server Error: /docs/
Traceback (most recent call last):
  File "/Library/Frameworks/Python.framework/Versions/3.7/lib/python3.7/site-packages/django/core/handlers/exception.py", line 35, in inner
    response = get_response(request)
  File "/Library/Frameworks/Python.framework/Versions/3.7/lib/python3.7/site-packages/django/core/handlers/base.py", line 158, in _get_response
    response = self.process_exception_by_middleware(e, request)
  File "/Library/Frameworks/Python.framework/Versions/3.7/lib/python3.7/site-packages/django/core/handlers/base.py", line 156, in _get_response
    response = response.render()
  File "/Library/Frameworks/Python.framework/Versions/3.7/lib/python3.7/site-packages/django/template/response.py", line 106, in render
    self.content = self.rendered_content
  File "/Library/Frameworks/Python.framework/Versions/3.7/lib/python3.7/site-packages/rest_framework/response.py", line 72, in rendered_content
    ret = renderer.render(self.data, accepted_media_type, context)
  File "/Library/Frameworks/Python.framework/Versions/3.7/lib/python3.7/site-packages/rest_framework_swagger/renderers.py", line 59, in render
    renderer_context
  File "/Library/Frameworks/Python.framework/Versions/3.7/lib/python3.7/site-packages/django/shortcuts.py", line 36, in render
    content = loader.render_to_string(template_name, context, request, using=using)
  File "/Library/Frameworks/Python.framework/Versions/3.7/lib/python3.7/site-packages/django/template/loader.py", line 61, in render_to_string
    template = get_template(template_name, using=using)
  File "/Library/Frameworks/Python.framework/Versions/3.7/lib/python3.7/site-packages/django/template/loader.py", line 19, in get_template
    raise TemplateDoesNotExist(template_name, chain=chain)
django.template.exceptions.TemplateDoesNotExist: rest_framework_swagger/index.html
2019-05-15 15:39:01,408,1028,django.server,ERROR,basehttp.py:124,"GET /docs/ HTTP/1.1" 500 93243
2019-05-15 15:42:34,759,1085,django.request,ERROR,exception.py:118,Internal Server Error: /docs/
Traceback (most recent call last):
  File "/Library/Frameworks/Python.framework/Versions/3.7/lib/python3.7/site-packages/django/urls/base.py", line 74, in reverse
    extra, resolver = resolver.namespace_dict[ns]
KeyError: 'rest_framework'

During handling of the above exception, another exception occurred:

Traceback (most recent call last):
  File "/Library/Frameworks/Python.framework/Versions/3.7/lib/python3.7/site-packages/django/core/handlers/exception.py", line 35, in inner
    response = get_response(request)
  File "/Library/Frameworks/Python.framework/Versions/3.7/lib/python3.7/site-packages/django/core/handlers/base.py", line 158, in _get_response
    response = self.process_exception_by_middleware(e, request)
  File "/Library/Frameworks/Python.framework/Versions/3.7/lib/python3.7/site-packages/django/core/handlers/base.py", line 156, in _get_response
    response = response.render()
  File "/Library/Frameworks/Python.framework/Versions/3.7/lib/python3.7/site-packages/django/template/response.py", line 106, in render
    self.content = self.rendered_content
  File "/Library/Frameworks/Python.framework/Versions/3.7/lib/python3.7/site-packages/rest_framework/response.py", line 72, in rendered_content
    ret = renderer.render(self.data, accepted_media_type, context)
  File "/Library/Frameworks/Python.framework/Versions/3.7/lib/python3.7/site-packages/rest_framework_swagger/renderers.py", line 55, in render
    self.set_context(renderer_context)
  File "/Library/Frameworks/Python.framework/Versions/3.7/lib/python3.7/site-packages/rest_framework_swagger/renderers.py", line 65, in set_context
    renderer_context.update(self.get_auth_urls())
  File "/Library/Frameworks/Python.framework/Versions/3.7/lib/python3.7/site-packages/rest_framework_swagger/renderers.py", line 72, in get_auth_urls
    urls['LOGIN_URL'] = resolve_url(swagger_settings.LOGIN_URL)
  File "/Library/Frameworks/Python.framework/Versions/3.7/lib/python3.7/site-packages/django/shortcuts.py", line 149, in resolve_url
    return reverse(to, args=args, kwargs=kwargs)
  File "/Library/Frameworks/Python.framework/Versions/3.7/lib/python3.7/site-packages/django/urls/base.py", line 84, in reverse
    raise NoReverseMatch("%s is not a registered namespace" % key)
django.urls.exceptions.NoReverseMatch: 'rest_framework' is not a registered namespace
2019-05-15 15:42:34,872,1085,django.server,ERROR,basehttp.py:124,"GET /docs/ HTTP/1.1" 500 100790
2019-05-15 15:42:36,317,1085,django.request,ERROR,exception.py:118,Internal Server Error: /docs/
Traceback (most recent call last):
  File "/Library/Frameworks/Python.framework/Versions/3.7/lib/python3.7/site-packages/django/urls/base.py", line 74, in reverse
    extra, resolver = resolver.namespace_dict[ns]
KeyError: 'rest_framework'

During handling of the above exception, another exception occurred:

Traceback (most recent call last):
  File "/Library/Frameworks/Python.framework/Versions/3.7/lib/python3.7/site-packages/django/core/handlers/exception.py", line 35, in inner
    response = get_response(request)
  File "/Library/Frameworks/Python.framework/Versions/3.7/lib/python3.7/site-packages/django/core/handlers/base.py", line 158, in _get_response
    response = self.process_exception_by_middleware(e, request)
  File "/Library/Frameworks/Python.framework/Versions/3.7/lib/python3.7/site-packages/django/core/handlers/base.py", line 156, in _get_response
    response = response.render()
  File "/Library/Frameworks/Python.framework/Versions/3.7/lib/python3.7/site-packages/django/template/response.py", line 106, in render
    self.content = self.rendered_content
  File "/Library/Frameworks/Python.framework/Versions/3.7/lib/python3.7/site-packages/rest_framework/response.py", line 72, in rendered_content
    ret = renderer.render(self.data, accepted_media_type, context)
  File "/Library/Frameworks/Python.framework/Versions/3.7/lib/python3.7/site-packages/rest_framework_swagger/renderers.py", line 55, in render
    self.set_context(renderer_context)
  File "/Library/Frameworks/Python.framework/Versions/3.7/lib/python3.7/site-packages/rest_framework_swagger/renderers.py", line 65, in set_context
    renderer_context.update(self.get_auth_urls())
  File "/Library/Frameworks/Python.framework/Versions/3.7/lib/python3.7/site-packages/rest_framework_swagger/renderers.py", line 72, in get_auth_urls
    urls['LOGIN_URL'] = resolve_url(swagger_settings.LOGIN_URL)
  File "/Library/Frameworks/Python.framework/Versions/3.7/lib/python3.7/site-packages/django/shortcuts.py", line 149, in resolve_url
    return reverse(to, args=args, kwargs=kwargs)
  File "/Library/Frameworks/Python.framework/Versions/3.7/lib/python3.7/site-packages/django/urls/base.py", line 84, in reverse
    raise NoReverseMatch("%s is not a registered namespace" % key)
django.urls.exceptions.NoReverseMatch: 'rest_framework' is not a registered namespace
2019-05-15 15:42:36,378,1085,django.server,ERROR,basehttp.py:124,"GET /docs/ HTTP/1.1" 500 100791
